2025-01-30 14:35:12,908 - ERROR - Erro ao processar sequenciamento: [Errno 2] No such file or directory: 'matches.fa.cap.contigs'
Traceback (most recent call last):
  File "/home/bioinformatica/Documentos/montagem/tela.py", line 49, in iniciar
    self.processar_sequenciamento(values)
  File "/home/bioinformatica/Documentos/montagem/tela.py", line 94, in processar_sequenciamento
    contig_final, tamanho = self.modo_turbo(diretorio, diretorio2, paired, rev, kmer, contig)
                            ^^^^^^^^^^^^^^^^^^^^^^^^^^^^^^^^^^^^^^^^^^^^^^^^^^^^^^^^^^^^^^^^^
  File "/home/bioinformatica/Documentos/montagem/tela.py", line 161, in modo_turbo
    contig_fim = self.realizar_montagem(contig, turbo=True)
                 ^^^^^^^^^^^^^^^^^^^^^^^^^^^^^^^^^^^^^^^^^^
  File "/home/bioinformatica/Documentos/montagem/tela.py", line 279, in realizar_montagem
    with open('matches.fa.cap.contigs', 'r') as arquivo:
         ^^^^^^^^^^^^^^^^^^^^^^^^^^^^^^^^^^^
FileNotFoundError: [Errno 2] No such file or directory: 'matches.fa.cap.contigs'
2025-01-30 14:36:46,978 - ERROR - Erro ao processar sequenciamento: [Errno 2] No such file or directory: 'matches.fa.cap.contigs'
Traceback (most recent call last):
  File "/home/bioinformatica/Documentos/montagem/tela.py", line 49, in iniciar
    self.processar_sequenciamento(values)
  File "/home/bioinformatica/Documentos/montagem/tela.py", line 94, in processar_sequenciamento
    contig_final, tamanho = self.modo_turbo(diretorio, diretorio2, paired, rev, kmer, contig)
                            ^^^^^^^^^^^^^^^^^^^^^^^^^^^^^^^^^^^^^^^^^^^^^^^^^^^^^^^^^^^^^^^^^
  File "/home/bioinformatica/Documentos/montagem/tela.py", line 161, in modo_turbo
    contig_fim = self.realizar_montagem(contig, turbo=True)
                 ^^^^^^^^^^^^^^^^^^^^^^^^^^^^^^^^^^^^^^^^^^
  File "/home/bioinformatica/Documentos/montagem/tela.py", line 279, in realizar_montagem
    with open('matches.fa.cap.contigs', 'r') as arquivo:
         ^^^^^^^^^^^^^^^^^^^^^^^^^^^^^^^^^^^
FileNotFoundError: [Errno 2] No such file or directory: 'matches.fa.cap.contigs'
2025-01-30 14:39:26,944 - ERROR - Erro ao processar sequenciamento: [Errno 2] No such file or directory: 'matches.fa.cap.contigs'
Traceback (most recent call last):
  File "/home/bioinformatica/Documentos/montagem/tela.py", line 49, in iniciar
    self.processar_sequenciamento(values)
  File "/home/bioinformatica/Documentos/montagem/tela.py", line 94, in processar_sequenciamento
    contig_final, tamanho = self.modo_turbo(diretorio, diretorio2, paired, rev, kmer, contig)
                            ^^^^^^^^^^^^^^^^^^^^^^^^^^^^^^^^^^^^^^^^^^^^^^^^^^^^^^^^^^^^^^^^^
  File "/home/bioinformatica/Documentos/montagem/tela.py", line 161, in modo_turbo
    contig_fim = self.realizar_montagem(contig, turbo=True)
                 ^^^^^^^^^^^^^^^^^^^^^^^^^^^^^^^^^^^^^^^^^^
  File "/home/bioinformatica/Documentos/montagem/tela.py", line 279, in realizar_montagem
    with open('matches.fa.cap.contigs', 'r') as arquivo:
         ^^^^^^^^^^^^^^^^^^^^^^^^^^^^^^^^^^^
FileNotFoundError: [Errno 2] No such file or directory: 'matches.fa.cap.contigs'
2025-01-31 13:37:53,377 - ERROR - Erro ao processar sequenciamento: [Errno 2] No such file or directory: 'matches.fa.cap.contigs'
Traceback (most recent call last):
  File "/home/bioinformatica/Documentos/montagem/tela.py", line 49, in iniciar
    self.processar_sequenciamento(values)
  File "/home/bioinformatica/Documentos/montagem/tela.py", line 94, in processar_sequenciamento
    contig_final, tamanho = self.modo_turbo(diretorio, diretorio2, paired, rev, kmer, contig)
                            ^^^^^^^^^^^^^^^^^^^^^^^^^^^^^^^^^^^^^^^^^^^^^^^^^^^^^^^^^^^^^^^^^
  File "/home/bioinformatica/Documentos/montagem/tela.py", line 166, in modo_turbo
    contig_fim = self.realizar_montagem(contig, turbo=True)
                 ^^^^^^^^^^^^^^^^^^^^^^^^^^^^^^^^^^^^^^^^^^
  File "/home/bioinformatica/Documentos/montagem/tela.py", line 290, in realizar_montagem
    with open('matches.fa.cap.contigs', 'r') as arquivo:
         ^^^^^^^^^^^^^^^^^^^^^^^^^^^^^^^^^^^
FileNotFoundError: [Errno 2] No such file or directory: 'matches.fa.cap.contigs'
2025-01-31 13:45:11,330 - ERROR - Erro ao processar sequenciamento: [Errno 2] No such file or directory: 'matches.fa.cap.contigs'
Traceback (most recent call last):
  File "/home/bioinformatica/Documentos/montagem/tela.py", line 49, in iniciar
    self.processar_sequenciamento(values)
  File "/home/bioinformatica/Documentos/montagem/tela.py", line 94, in processar_sequenciamento
    contig_final, tamanho = self.modo_turbo(diretorio, diretorio2, paired, rev, kmer, contig)
                            ^^^^^^^^^^^^^^^^^^^^^^^^^^^^^^^^^^^^^^^^^^^^^^^^^^^^^^^^^^^^^^^^^
  File "/home/bioinformatica/Documentos/montagem/tela.py", line 166, in modo_turbo
    contig_fim = self.realizar_montagem(contig, turbo=True, iteracao = volta + 1)
                 ^^^^^^^^^^^^^^^^^^^^^^^^^^^^^^^^^^^^^^^^^^^^^^^^^^^^^^^^^^^^^^^^
  File "/home/bioinformatica/Documentos/montagem/tela.py", line 299, in realizar_montagem
    with open('matches.fa.cap.contigs', 'r') as arquivo:
         ^^^^^^^^^^^^^^^^^^^^^^^^^^^^^^^^^^^
FileNotFoundError: [Errno 2] No such file or directory: 'matches.fa.cap.contigs'
2025-01-31 14:17:38,030 - ERROR - Erro ao processar sequenciamento: TelaPython.realizar_montagem() missing 1 required positional argument: 'iteracao'
Traceback (most recent call last):
  File "/home/bioinformatica/Documentos/montagem/tela.py", line 49, in iniciar
    self.processar_sequenciamento(values)
  File "/home/bioinformatica/Documentos/montagem/tela.py", line 96, in processar_sequenciamento
    contig_final, tamanho = self.modo_normal(diretorio, diretorio2, paired, rev, kmer, contig)
                            ^^^^^^^^^^^^^^^^^^^^^^^^^^^^^^^^^^^^^^^^^^^^^^^^^^^^^^^^^^^^^^^^^^
  File "/home/bioinformatica/Documentos/montagem/tela.py", line 216, in modo_normal
    contig_fim = self.realizar_montagem(contig, turbo=False)
                 ^^^^^^^^^^^^^^^^^^^^^^^^^^^^^^^^^^^^^^^^^^^
TypeError: TelaPython.realizar_montagem() missing 1 required positional argument: 'iteracao'
2025-01-31 14:22:37,241 - ERROR - Erro ao processar sequenciamento: TelaPython.realizar_montagem() missing 1 required positional argument: 'iteracao'
Traceback (most recent call last):
  File "/home/bioinformatica/Documentos/montagem/tela.py", line 49, in iniciar
    self.processar_sequenciamento(values)
  File "/home/bioinformatica/Documentos/montagem/tela.py", line 96, in processar_sequenciamento
    contig_final, tamanho = self.modo_normal(diretorio, diretorio2, paired, rev, kmer, contig)
                            ^^^^^^^^^^^^^^^^^^^^^^^^^^^^^^^^^^^^^^^^^^^^^^^^^^^^^^^^^^^^^^^^^^
  File "/home/bioinformatica/Documentos/montagem/tela.py", line 216, in modo_normal
    contig_fim = self.realizar_montagem(contig, turbo=False, iteracao=1)
                 ^^^^^^^^^^^^^^^^^^^^^^^^^^^^^^^^^^^^^^^^^^^
TypeError: TelaPython.realizar_montagem() missing 1 required positional argument: 'iteracao'
2025-02-05 13:22:49,461 - ERROR - Erro ao processar sequenciamento: TelaPython.contig_with_most_reads() takes 1 positional argument but 2 were given
Traceback (most recent call last):
  File "/home/bioinformatica/Documentos/montagem/tela.py", line 49, in iniciar
    self.processar_sequenciamento(values)
  File "/home/bioinformatica/Documentos/montagem/tela.py", line 94, in processar_sequenciamento
    contig_final, tamanho = self.modo_turbo(diretorio, diretorio2, paired, rev, kmer, contig, voltar, voltar_nuc)
                            ^^^^^^^^^^^^^^^^^^^^^^^^^^^^^^^^^^^^^^^^^^^^^^^^^^^^^^^^^^^^^^^^^^^^^^^^^^^^^^^^^^^^^
  File "/home/bioinformatica/Documentos/montagem/tela.py", line 166, in modo_turbo
    contig_fim = self.realizar_montagem(contig, turbo=True, iteracao = volta + 1)
                 ^^^^^^^^^^^^^^^^^^^^^^^^^^^^^^^^^^^^^^^^^^^^^^^^^^^^^^^^^^^^^^^^
  File "/home/bioinformatica/Documentos/montagem/tela.py", line 328, in realizar_montagem
    id_contig_formado, num_reads = self.contig_with_most_reads("consenso")
                                   ^^^^^^^^^^^^^^^^^^^^^^^^^^^^^^^^^^^^^^^
TypeError: TelaPython.contig_with_most_reads() takes 1 positional argument but 2 were given
2025-02-05 13:30:19,012 - ERROR - Erro ao processar sequenciamento: TelaPython.contig_with_most_reads() takes 1 positional argument but 2 were given
Traceback (most recent call last):
  File "/home/bioinformatica/Documentos/montagem/tela.py", line 49, in iniciar
    self.processar_sequenciamento(values)
  File "/home/bioinformatica/Documentos/montagem/tela.py", line 94, in processar_sequenciamento
    contig_final, tamanho = self.modo_turbo(diretorio, diretorio2, paired, rev, kmer, contig, voltar, voltar_nuc)
                            ^^^^^^^^^^^^^^^^^^^^^^^^^^^^^^^^^^^^^^^^^^^^^^^^^^^^^^^^^^^^^^^^^^^^^^^^^^^^^^^^^^^^^
  File "/home/bioinformatica/Documentos/montagem/tela.py", line 166, in modo_turbo
    contig_fim = self.realizar_montagem(contig, turbo=True, iteracao = volta + 1)
                 ^^^^^^^^^^^^^^^^^^^^^^^^^^^^^^^^^^^^^^^^^^^^^^^^^^^^^^^^^^^^^^^^
  File "/home/bioinformatica/Documentos/montagem/tela.py", line 328, in realizar_montagem
    id_contig_formado, num_reads = self.contig_with_most_reads("consenso")
                                   ^^^^^^^^^^^^^^^^^^^^^^^^^^^^^^^^^^^^^^^
TypeError: TelaPython.contig_with_most_reads() takes 1 positional argument but 2 were given
2025-02-05 13:32:57,609 - ERROR - Erro ao processar sequenciamento: TelaPython.contig_with_most_reads() takes 1 positional argument but 2 were given
Traceback (most recent call last):
  File "/home/bioinformatica/Documentos/montagem/tela.py", line 49, in iniciar
    self.processar_sequenciamento(values)
  File "/home/bioinformatica/Documentos/montagem/tela.py", line 94, in processar_sequenciamento
    contig_final, tamanho = self.modo_turbo(diretorio, diretorio2, paired, rev, kmer, contig, voltar, voltar_nuc)
                            ^^^^^^^^^^^^^^^^^^^^^^^^^^^^^^^^^^^^^^^^^^^^^^^^^^^^^^^^^^^^^^^^^^^^^^^^^^^^^^^^^^^^^
  File "/home/bioinformatica/Documentos/montagem/tela.py", line 166, in modo_turbo
    contig_fim = self.realizar_montagem(contig, turbo=True, iteracao = volta + 1)
                 ^^^^^^^^^^^^^^^^^^^^^^^^^^^^^^^^^^^^^^^^^^^^^^^^^^^^^^^^^^^^^^^^
  File "/home/bioinformatica/Documentos/montagem/tela.py", line 328, in realizar_montagem
    tupla = self.contig_with_most_reads("consenso")
            ^^^^^^^^^^^^^^^^^^^^^^^^^^^^^^^^^^^^^^^
TypeError: TelaPython.contig_with_most_reads() takes 1 positional argument but 2 were given
2025-02-05 13:34:27,680 - ERROR - Erro ao processar sequenciamento: TelaPython.contig_with_most_reads() takes 1 positional argument but 2 were given
Traceback (most recent call last):
  File "/home/bioinformatica/Documentos/montagem/tela.py", line 49, in iniciar
    self.processar_sequenciamento(values)
  File "/home/bioinformatica/Documentos/montagem/tela.py", line 94, in processar_sequenciamento
    contig_final, tamanho = self.modo_turbo(diretorio, diretorio2, paired, rev, kmer, contig, voltar, voltar_nuc)
                            ^^^^^^^^^^^^^^^^^^^^^^^^^^^^^^^^^^^^^^^^^^^^^^^^^^^^^^^^^^^^^^^^^^^^^^^^^^^^^^^^^^^^^
  File "/home/bioinformatica/Documentos/montagem/tela.py", line 166, in modo_turbo
    contig_fim = self.realizar_montagem(contig, turbo=True, iteracao = volta + 1)
                 ^^^^^^^^^^^^^^^^^^^^^^^^^^^^^^^^^^^^^^^^^^^^^^^^^^^^^^^^^^^^^^^^
  File "/home/bioinformatica/Documentos/montagem/tela.py", line 328, in realizar_montagem
    tupla = self.contig_with_most_reads("consenso")
            ^^^^^^^^^^^^^^^^^^^^^^^^^^^^^^^^^^^^^^^
TypeError: TelaPython.contig_with_most_reads() takes 1 positional argument but 2 were given
